<?xml version="1.0" encoding="utf-8"?>
<!-- This URDF was automatically created by SolidWorks to URDF Exporter! Originally created by Stephen Brawner (brawner@gmail.com) 
     Commit Version: 1.6.0-4-g7f85cfe  Build Version: 1.6.7995.38578
     For more information, please see http://wiki.ros.org/sw_urdf_exporter -->
<robot
  name="OpenLoog">
  <mujoco>
    <compiler
    	meshdir="../meshes"
    	discardvisual="false" />
  </mujoco>
  <!--balanceinertia="true" -->

  <link
    name="base_link">
       <visual>
      <origin xyz="0 0 0" rpy="0 0 0"/>
      <geometry>
        <box size="0.02 0.02 0.02"/> 
      </geometry>
      <material name="box_color">
        <color rgba="1 0 0 1"/> 
      </material>
    </visual>
    <collision>
      <origin xyz="0 0 0" rpy="0 0 0"/>
      <geometry>
        <box size="0.02 0.02 0.02"/>
      </geometry>
    </collision>
  </link>

  
  <!--left arm-->
  <link
    name="Link_arm_l_01">
    <inertial>
      <origin
        xyz="-0.00449464987882542 0.0382942125981936 -1.874402432607E-06"
        rpy="0 0 0" />
      <mass
        value="0.756406339732892" />
      <inertia
        ixx="0.000587115683146372"
        ixy="-2.98026052651538E-07"
        ixz="5.83781087215966E-09"
        iyy="0.000803052813361661"
        iyz="-3.66476835396106E-08"
        izz="0.000842985653484675" />
    </inertial>
    <visual>
      <origin
        xyz="0 0 0"
        rpy="0 0 0" />
      <geometry>
        <mesh
          filename="../meshes/Link_arm_l_01.STL" />
      </geometry>
      <material
        name="">
        <color
          rgba="0.698039215686274 0.698039215686274 0.698039215686274 1" />
      </material>
    </visual>
    <collision>
      <origin
        xyz="0 0 0"
        rpy="0 0 0" />
      <geometry>
        <mesh
          filename="../meshes/Link_arm_l_01.STL" />
      </geometry>
    </collision>
  </link>
  <joint
    name="J_arm_l_01"
    type="revolute">
    <origin
      xyz="0 0 0"
      rpy="0 0 0" />
    <parent
      link="base_link" />
    <child
      link="Link_arm_l_01" />
    <axis
      xyz="0 1 0" />
    <limit
      lower="-2.96706"
      upper="2.96706"
      effort="80"
      velocity="3.14" />
  </joint>

  <link
    name="Link_arm_l_02">
    <inertial>
      <origin
        xyz="-0.042 0.0674307499121858 1.38777878078145E-17"
        rpy="0 0 0" />
      <mass
        value="0.984999996273518" />
      <inertia
        ixx="0.0017309882399251"
        ixy="1.48322871384691E-19"
        ixz="1.94588987195478E-19"
        iyy="0.00115401958000568"
        iyz="6.15989345249147E-19"
        izz="0.00226269324370836" />
    </inertial>
    <visual>
      <origin
        xyz="0 0 0"
        rpy="0 0 0" />
      <geometry>
        <mesh
          filename="../meshes/Link_arm_l_02.STL" />
      </geometry>
      <material
        name="">
        <color
          rgba="0.698039215686274 0.698039215686274 0.698039215686274 1" />
      </material>
    </visual>
    <collision>
      <origin
        xyz="0 0 0"
        rpy="0 0 0" />
      <geometry>
        <mesh
          filename="../meshes/Link_arm_l_02.STL" />
      </geometry>
    </collision>
  </link>
  <joint
    name="J_arm_l_02"
    type="revolute">
    <origin
      xyz="0.042 0.041 0"
      rpy="0 0 0" />
    <parent
      link="Link_arm_l_01" />
    <child
      link="Link_arm_l_02" />
    <axis
      xyz="-1 0 0" />
    <limit
      lower="-1.83260"
      upper="1.83260"
      effort="80"
      velocity="3.14" />
  </joint>

    <link
    name="Link_arm_l_03">
    <inertial>
      <origin
        xyz="0.00141357502419956 0.164662742175383 0.0207578924800774"
        rpy="0 0 0" />
      <mass
        value="0.958999855228925" />
      <inertia
        ixx="0.00206438134078715"
        ixy="-1.82014067823508E-05"
        ixz="-5.12831369639908E-06"
        iyy="0.000805354129266641"
        iyz="-0.000255265992194607"
        izz="0.00205099914609259" />
    </inertial>
    <visual>
      <origin
        xyz="0 0 0"
        rpy="0 0 0" />
      <geometry>
        <mesh
          filename="../meshes/Link_arm_l_03.STL" />
      </geometry>
      <material
        name="">
        <color
          rgba="0.698039215686274 0.698039215686274 0.698039215686274 1" />
      </material>
    </visual>
    <collision>
      <origin
        xyz="0 0 0"
        rpy="0 0 0" />
      <geometry>
        <mesh
          filename="../meshes/Link_arm_l_03.STL" />
      </geometry>
    </collision>
  </link>
  <joint
    name="J_arm_l_03"
    type="revolute">
    <origin
      xyz="-0.042 0.1226 0"
      rpy="0 0 0" />
    <parent
      link="Link_arm_l_02" />
    <child
      link="Link_arm_l_03" />
    <axis
      xyz="0 1 0" />
    <limit
      lower="-2.96706"
      upper="2.96706"
      effort="48"
      velocity="3.14" />
  </joint>

  <link
    name="Link_arm_l_04">
    <inertial>
      <origin
        xyz="0.038726985904266 0.0607672244593032 -0.0210032450980798"
        rpy="0 0 0" />
      <mass
        value="0.60000012303258" />
      <inertia
        ixx="0.000703976141425558"
        ixy="2.02301178076816E-05"
        ixz="-1.12633779930363E-05"
        iyy="0.000680850033983237"
        iyz="0.000105852227353173"
        izz="0.00106526266740194" />
    </inertial>
    <visual>
      <origin
        xyz="0 0 0"
        rpy="0 0 0" />
      <geometry>
        <mesh
          filename="../meshes/Link_arm_l_04.STL" />
      </geometry>
      <material
        name="">
        <color
          rgba="0.698039215686274 0.698039215686274 0.698039215686274 1" />
      </material>
    </visual>
    <collision>
      <origin
        xyz="0 0 0"
        rpy="0 0 0" />
      <geometry>
        <mesh
          filename="../meshes/Link_arm_l_04.STL" />
      </geometry>
    </collision>
  </link>
  <joint
    name="J_arm_l_04"
    type="revolute">
    <origin
      xyz="-0.0353 0.1774 0.024"
      rpy="0 0 0" />
    <parent
      link="Link_arm_l_03" />
    <child
      link="Link_arm_l_04" />
    <axis
      xyz="1 0 0" />
    <limit
      lower="0"
      upper="2.96706"
      effort="48"
      velocity="3.14" />
  </joint>

    <link
    name="Link_arm_l_05">
    <inertial>
      <origin
        xyz="-3.2712E-05 0.068658 -0.00011178"
        rpy="0 0 0" />
      <mass
        value="0.68976" />
      <inertia
        ixx="0.0025225"
        ixy="-4E-07"
        ixz="-8E-07"
        iyy="0.0004487"
        iyz="-3.1E-06"
        izz="0.0024111" />
    </inertial>
    <visual>
      <origin
        xyz="0 0 0"
        rpy="0 0 0" />
      <geometry>
        <mesh
          filename="../meshes/Link_arm_l_05.STL" />
      </geometry>
      <material
        name="">
        <color
          rgba="0.69804 0.69804 0.69804 1" />
      </material>
    </visual>
    <collision>
      <origin
        xyz="0 0 0"
        rpy="0 0 0" />
      <geometry>
        <mesh
          filename="../meshes/Link_arm_l_05.STL" />
      </geometry>
    </collision>
  </link>
  <joint
    name="J_arm_l_05"
    type="revolute">
    <origin
      xyz="0.0353 0.1035 -0.024"
      rpy="0 0 0" />
    <parent
      link="Link_arm_l_04" />
    <child
      link="Link_arm_l_05" />
    <axis
      xyz="0 1 0" />
    <limit
      lower="-2.96706"
      upper="2.96706"
      effort="12.4"
      velocity="6.28" />
  </joint>

  <link
    name="Link_arm_l_06">
    <inertial>
      <origin
        xyz="-0.0260776548825596 8.95877202866657E-07 0.00166373234012217"
        rpy="0 0 0" />
      <mass
        value="0.280000012776158" />
      <inertia
        ixx="0.000145596926990102"
        ixy="-7.70263046256849E-10"
        ixz="2.14557176368931E-07"
        iyy="0.000156926535065694"
        iyz="2.41022657678511E-09"
        izz="0.000104981940665913" />
    </inertial>
    <visual>
      <origin
        xyz="0 0 0"
        rpy="0 0 0" />
      <geometry>
        <mesh
          filename="../meshes/Link_arm_l_06.STL" />
      </geometry>
      <material
        name="">
        <color
          rgba="0.698039215686274 0.698039215686274 0.698039215686274 1" />
      </material>
    </visual>
    <collision>
      <origin
        xyz="0 0 0"
        rpy="0 0 0" />
      <geometry>
        <mesh
          filename="../meshes/Link_arm_l_06.STL" />
      </geometry>
    </collision>
  </link>
  <joint
    name="J_arm_l_06"
    type="revolute">
    <origin
      xyz="0.0265 0.1965 0"
      rpy="0 0 0" />
    <parent
      link="Link_arm_l_05" />
    <child
      link="Link_arm_l_06" />
    <axis
      xyz="-1 0 0" />
    <limit
      lower="-1.8326"
      upper="1.8326"
      effort="12.4"
      velocity="6.28" />
  </joint>

 

  <!--left flange link-->
  <link
    name="left_flange_link">
    <inertial>
      <origin
        xyz="0.0012764 0.064193 0.0010309"
        rpy="0 0 0" />
      <mass
        value="1.572" />
      <inertia
        ixx="0.0029967"
        ixy="-4.155E-05"
        ixz="-9.9382E-06"
        iyy="0.0009617"
        iyz="-5.1855E-05"
        izz="0.0035617" />
    </inertial>
    <visual>
      <origin
        xyz="0 0 0"
        rpy="0 0 0" />
      <geometry>
        <mesh
          filename="../meshes/hand_flange.STL" />
      </geometry>
      <material
        name="">
        <color
          rgba="0.52941 0.54902 0.54902 1" />
      </material>
    </visual>
    <collision>
      <origin
        xyz="0 0 0"
        rpy="0 0 0" />
      <geometry>
        <mesh
          filename="../meshes/hand_flange.STL" />
      </geometry>
    </collision>
  </link>

  <!--joint for left arm and left flange-->
  <joint
    name="J_arm_l_flange"
    type="revolute">
    <origin
      xyz="-0.025 0 0"
      rpy="0 1.57 -1.57" />
    <parent
      link="Link_arm_l_06" />
    <child
      link="left_flange_link" />
    <axis
      xyz="1 0 0" />
    <limit
      lower="-1.04720"
      upper="1.04720"
      effort="12.4"
      velocity="6.28" />
  </joint> 

  <link
    name="wrist_link">
       <visual>
      <origin xyz="0 0 0" rpy="0 0 0"/>
      <geometry>
        <box size="0.01 0.01 0.01"/> 
      </geometry>
      <material name="box_color">
        <color rgba="1 0 0 1"/> 
      </material>
    </visual>
    <collision>
      <origin xyz="0 0 0" rpy="0 0 0"/>
      <geometry>
        <box size="0.01 0.01 0.01"/>
      </geometry>
    </collision>
  </link>
  <joint 
    name="wrist_link_joint" 
    type="fixed">
    <origin
    xyz="0 0 -0.055"
    rpy="0 0 0" />
    <parent link="left_flange_link"/>
    <child link="wrist_link"/>
  </joint>

</robot>

  